Workbook

Sheet Raw_Dataset
A1: Month | B1: Product | C1: Actual Monthly Sales (units) | D1: Previous Company Forecast (units) | E1: Defect Rate (%) | F1: Labour Hours | G1: Available Production Capacity (units) | H1: Unit Production Cost (EGP) | I1: Unit Selling Price (EGP) | J1: Profit
A2: Jan | B2: Nile Espresso | C2: 4200 | D2: 4000 | E2: 2.8 | F2: 420 | G2: 5000 | H2: 180 | I2: 300 | J2: =I2-H2 -> 120
A3: Feb | B3: Nile Espresso | C3: 4000 | D3: 4200 | E3: 2.5 | F3: 400 | G3: 5000 | H3: 180 | I3: 300 | J3: =I3-H3 -> 120
A4: Mar | B4: Nile Espresso | C4: 4600 | D4: 4300 | E4: 3.1 | F4: 460 | G4: 5000 | H4: 180 | I4: 300 | J4: =I4-H4 -> 120
A5: Apr | B5: Nile Espresso | C5: 4800 | D5: 4700 | E5: 3.8 | F5: 480 | G5: 5000 | H5: 180 | I5: 300 | J5: =I5-H5 -> 120
A6: May | B6: Nile Espresso | C6: 5200 | D6: 4900 | E6: 3.4 | F6: 520 | G6: 5000 | H6: 180 | I6: 300 | J6: =I6-H6 -> 120
A7: Jun | B7: Nile Espresso | C7: 5600 | D7: 5400 | E7: 4.2 | F7: 560 | G7: 5500 | H7: 185 | I7: 300 | J7: =I7-H7 -> 115
A8: Jul | B8: Nile Espresso | C8: 6100 | D8: 5800 | E8: 4.8 | F8: 610 | G8: 5500 | H8: 185 | I8: 300 | J8: =I8-H8 -> 115
A9: Aug | B9: Nile Espresso | C9: 5900 | D9: 6200 | E9: 4.1 | F9: 590 | G9: 5500 | H9: 185 | I9: 300 | J9: =I9-H9 -> 115
A10: Sep | B10: Nile Espresso | C10: 5500 | D10: 5700 | E10: 3.6 | F10: 550 | G10: 5500 | H10: 185 | I10: 300 | J10: =I10-H10 -> 115
A11: Oct | B11: Nile Espresso | C11: 6200 | D11: 5800 | E11: 5.2 | F11: 620 | G11: 6000 | H11: 190 | I11: 300 | J11: =I11-H11 -> 110
A12: Nov | B12: Nile Espresso | C12: 6800 | D12: 6500 | E12: 4.7 | F12: 680 | G12: 6000 | H12: 190 | I12: 300 | J12: =I12-H12 -> 110
A13: Dec | B13: Nile Espresso | C13: 7600 | D13: 7200 | E13: 5.8 | F13: 760 | G13: 6000 | H13: 190 | I13: 300 | J13: =I13-H13 -> 110
... A37: Dec | B37: Nile Cold Brew | C37: 7800 | D37: 7000 | E37: 6.5 | F37: 936 | G37: 4500 | H37: 105 | I37: 170 | J37: =I37-H37 -> 65

Sheet PivotTables
A3: Sum of Actual Monthly Sales (units) | B3: Column Labels
A4: Row Labels | B4: Cairo House Blend | C4: Nile Cold Brew | D4: Nile Espresso | E4: Grand Total | H4: Row Labels | I4: Sum of Actual Monthly Sales (units)
A5: Jan | B5: 6000 | C5: 2500 | D5: 4200 | E5: 12700 | H5: Cairo House Blend | I5: 91300
A6: Feb | B6: 5800 | C6: 2300 | D6: 4000 | E6: 12100 | H6: Nile Cold Brew | I6: 53900
A7: Mar | B7: 6500 | C7: 3000 | D7: 4600 | E7: 14100 | H7: Nile Espresso | I7: 66500
A8: Apr | B8: 6800 | C8: 3400 | D8: 4800 | E8: 15000 | H8: Grand Total | I8: 211700
A9: May | B9: 7200 | C9: 3900 | D9: 5200 | E9: 16300
A10: Jun | B10: 7600 | C10: 4500 | D10: 5600 | E10: 17700
A11: Jul | B11: 8200 | C11: 5200 | D11: 6100 | E11: 19500
A12: Aug | B12: 8000 | C12: 5000 | D12: 5900 | E12: 18900 | H12: Row Labels | I12: Sum of Profit
A13: Sep | B13: 7500 | C13: 4200 | D13: 5500 | E13: 17200 | H13: Cairo House Blend | I13: 910
A14: Oct | B14: 8400 | C14: 5600 | D14: 6200 | E14: 20200 | H14: Nile Cold Brew | I14: 850
A15: Nov | B15: 9100 | C15: 6500 | D15: 6800 | E15: 22400 | H15: Nile Espresso | I15: 1390
A16: Dec | B16: 10200 | C16: 7800 | D16: 7600 | E16: 25600 | H16: Grand Total | I16: 3150
A17: Grand Total | B17: 91300 | C17: 53900 | D17: 66500 | E17: 211700
H19: Row Labels | I19: Sum of Unit Selling Price (EGP)
H20: Cairo House Blend | I20: 2280
H21: Nile Cold Brew | I21: 2040
H22: Nile Espresso | I22: 3600
H23: Grand Total | I23: 7920
H26: Row Labels | I26: Sum of Unit Production Cost (EGP)
H27: Cairo House Blend | I27: 1370
H28: Nile Cold Brew | I28: 1190
H29: Nile Espresso | I29: 2210
H30: Grand Total | I30: 4770
H33: Row Labels | I33: Sum of Available Production Capacity (units)
H34: Cairo House Blend | I34: 89000
H35: Nile Cold Brew | I35: 45500
H36: Nile Espresso | I36: 65000
H37: Grand Total | I37: 199500
H40: Row Labels | I40: Sum of Actual Monthly Sales (units) | J40: Sum of Previous Company Forecast (units)
H41: Jan | I41: 12700 | J41: 12900
H42: Feb | I42: 12100 | J42: 12500
H43: Mar | I43: 14100 | J43: 13300
H44: Apr | I44: 15000 | J44: 14500
H45: May | I45: 16300 | J45: 15500
H46: Jun | I46: 17700 | J46: 17000
H47: Jul | I47: 19500 | J47: 18500
H48: Aug | I48: 18900 | J48: 19900
H49: Sep | I49: 17200 | J49: 18100
...

Sheet Dashboard
A2: Nile Coffee — Dashboard Analysis

Sheet Demand Forecasting
A2: Nile Espresso — Demand analysis and forecasting
A4: Period | B4: Sales (units) | C4: Month
A5: 1 | B5: =SUMIFS(Raw_Dataset!$C$2:$C$37,Raw_Dataset!$A$2:$A$37,C5,Raw_Dataset!$B$2:$B$37,"Nile Espresso") -> 4200 | C5: Jan
A6: 2 | B6: =SUMIFS(Raw_Dataset!$C$2:$C$37,Raw_Dataset!$A$2:$A$37,C6,Raw_Dataset!$B$2:$B$37,"Nile Espresso") -> 4000 | C6: Feb
A7: 3 | B7: =SUMIFS(Raw_Dataset!$C$2:$C$37,Raw_Dataset!$A$2:$A$37,C7,Raw_Dataset!$B$2:$B$37,"Nile Espresso") -> 4600 | C7: Mar
A8: 4 | B8: =SUMIFS(Raw_Dataset!$C$2:$C$37,Raw_Dataset!$A$2:$A$37,C8,Raw_Dataset!$B$2:$B$37,"Nile Espresso") -> 4800 | C8: Apr
A9: 5 | B9: =SUMIFS(Raw_Dataset!$C$2:$C$37,Raw_Dataset!$A$2:$A$37,C9,Raw_Dataset!$B$2:$B$37,"Nile Espresso") -> 5200 | C9: May
A10: 6 | B10: =SUMIFS(Raw_Dataset!$C$2:$C$37,Raw_Dataset!$A$2:$A$37,C10,Raw_Dataset!$B$2:$B$37,"Nile Espresso") -> 5600 | C10: Jun
A11: 7 | B11: =SUMIFS(Raw_Dataset!$C$2:$C$37,Raw_Dataset!$A$2:$A$37,C11,Raw_Dataset!$B$2:$B$37,"Nile Espresso") -> 6100 | C11: Jul
A12: 8 | B12: =SUMIFS(Raw_Dataset!$C$2:$C$37,Raw_Dataset!$A$2:$A$37,C12,Raw_Dataset!$B$2:$B$37,"Nile Espresso") -> 5900 | C12: Aug
A13: 9 | B13: =SUMIFS(Raw_Dataset!$C$2:$C$37,Raw_Dataset!$A$2:$A$37,C13,Raw_Dataset!$B$2:$B$37,"Nile Espresso") -> 5500 | C13: Sep
A14: 10 | B14: =SUMIFS(Raw_Dataset!$C$2:$C$37,Raw_Dataset!$A$2:$A$37,C14,Raw_Dataset!$B$2:$B$37,"Nile Espresso") -> 6200 | C14: Oct
A15: 11 | B15: =SUMIFS(Raw_Dataset!$C$2:$C$37,Raw_Dataset!$A$2:$A$37,C15,Raw_Dataset!$B$2:$B$37,"Nile Espresso") -> 6800 | C15: Nov
A16: 12 | B16: =SUMIFS(Raw_Dataset!$C$2:$C$37,Raw_Dataset!$A$2:$A$37,C16,Raw_Dataset!$B$2:$B$37,"Nile Espresso") -> 7600 | C16: Dec
A19: Simple moving average | F19: Window (months): | J19: =INDEX(D98:H98,1,MATCH(MIN(D108:H108),D108:H108,0)) -> 2
A21: Period | B21: Demand | D21: Forecast | E21: Error (A-F) | F21: |Error| | G21: Error^2
A22: =A5 -> 1 | B22: =B5 -> 4200 | J22: n | K22: =COUNT(E28:E33) -> 6
A23: =A6 -> 2 | B23: =B6 -> 4000 | J23: Sum absolute errors | K23: =SUM(F28:F33) -> 3800
A24: =A7 -> 3 | B24: =B7 -> 4600 | J24: Sum squared errors | K24: =SUM(G28:G33) -> 3105000
A25: =A8 -> 4 | B25: =B8 -> 4800
A26: =A9 -> 5 | B26: =B9 -> 5200
A27: =A10 -> 6 | B27: =B10 -> 5600 | J27: MAD | K27: =K23/K22 -> 633.33333
A28: =A11 -> 7 | B28: =B11 -> 6100 | D28: =INDEX(D100:H100,1,MATCH($J$19,$D$98:$H$98,0)) -> 5400 | E28: =B28-D28 -> 700 | F28: =ABS(E28) -> 700 | G28: =E28^2 -> 490000 | J28: MSE | K28: =K24/K22 -> 517500
A29: =A12 -> 8 | B29: =B12 -> 5900 | D29: =INDEX(D101:H101,1,MATCH($J$19,$D$98:$H$98,0)) -> 5850 | E29: =B29-D29 -> 50 | F29: =ABS(E29) -> 50 | G29: =E29^2 -> 2500
A30: =A13 -> 9 | B30: =B13 -> 5500 | D30: =INDEX(D102:H102,1,MATCH($J$19,$D$98:$H$98,0)) -> 6000 | E30: =B30-D30 -> -500 | F30: =ABS(E30) -> 500 | G30: =E30^2 -> 250000
A31: =A14 -> 10 | B31: =B14 -> 6200 | D31: =INDEX(D103:H103,1,MATCH($J$19,$D$98:$H$98,0)) -> 5700 | E31: =B31-D31 -> 500 | F31: =ABS(E31) -> 500 | G31: =E31^2 -> 250000
A32: =A15 -> 11 | B32: =B15 -> 6800 | D32: =INDEX(D104:H104,1,MATCH($J$19,$D$98:$H$98,0)) -> 5850 | E32: =B32-D32 -> 950 | F32: =ABS(E32) -> 950 | G32: =E32^2 -> 902500
A33: =A16 -> 12 | B33: =B16 -> 7600 | D33: =INDEX(D105:H105,1,MATCH($J$19,$D$98:$H$98,0)) -> 6500 | E33: =B33-D33 -> 1100 | F33: =ABS(E33) -> 1100 | G33: =E33^2 -> 1210000
A36: Linear Trend
A38: Period | B38: Demand | D38: Forecast | E38: Error (A-F) | F38: |Error| | G38: Error^2
A39: =A5 -> 1 | B39: =B5 -> 4200 | J39: n | K39: =COUNT(E45:E50) -> 6
A40: =A6 -> 2 | B40: =B6 -> 4000 | J40: Sum absolute errors | K40: =SUM(F45:F50) -> 2749.5238
A41: =A7 -> 3 | B41: =B7 -> 4600 | J41: Sum squared errors | K41: =SUM(G45:G50) -> 1741468.6
A42: =A8 -> 4 | B42: =B8 -> 4800
A43: =A9 -> 5 | B43: =B9 -> 5200
A44: =A10 -> 6 | B44: =B10 -> 5600 | J44: MAD | K44: =K40/K39 -> 458.25397
A45: =A11 -> 7 | B45: =B11 -> 6100 | D45: =INTERCEPT($B$54:B59,$A$54:A59)+SLOPE($B$54:B59,$A$54:A59)*A45 -> 5813.3333 | E45: =B45-D45 -> 286.66667 | F45: =ABS(E45) -> 286.66667 | G45: =E45^2 -> 82177.778 | J45: MSE | K45: =K41/K39 -> 290244.77
A46: =A12 -> 8 | B46: =B12 -> 5900 | D46: =INTERCEPT($B$54:B60,$A$54:A60)+SLOPE($B$54:B60,$A$54:A60)*A46 -> 6285.7143 | E46: =B46-D46 -> -385.71429 | F46: =ABS(E46) -> 385.71429 | G46: =E46^2 -> 148775.51
A47: =A13 -> 9 | B47: =B13 -> 5500 | D47: =INTERCEPT($B$54:B61,$A$54:A61)+SLOPE($B$54:B61,$A$54:A61)*A47 -> 6432.1429 | E47: =B47-D47 -> -932.14286 | F47: =ABS(E47) -> 932.14286 | G47: =E47^2 -> 868890.31
A48: =A14 -> 10 | B48: =B14 -> 6200 | D48: =INTERCEPT($B$54:B62,$A$54:A62)+SLOPE($B$54:B62,$A$54:A62)*A48 -> 6325 | E48: =B48-D48 -> -125 | F48: =ABS(E48) -> 125 | G48: =E48^2 -> 15625
...
